

Answer: The log is classified as 'Defective' because it contains the following error message:

\begin{code}
Traceback (most recent call last):
  File /mnt/c/WINDOWS/system32/workspace/masterarbeit/DevBench/benchmark_data/python/geotext/unit_tests/test_geotext.py, line 120, in test_country_mentions
    self.assertEqual(result, expected)
AssertionError: OrderedDict([('US', 3), ('RU', 1)]) != {'PE': 1, 'IE': 1, 'RU': 2}
\end{code}

This indicates that the test `test_country_mentions` in the file `test_geotext.py` failed.